[E 240131 12:43:21 3159352199:20] Historic Api failed: HTTPSConnectionPool(host='apiconnect.angelbroking.com', port=443): Max retries exceeded with url: /rest/secure/angelbroking/historical/v1/getCandleData (Caused by NewConnectionError('<urllib3.connection.HTTPSConnection object at 0x000001C8EED71290>: Failed to establish a new connection: [Errno 11001] getaddrinfo failed'))
    Traceback (most recent call last):
      File "C:\Users\mahan\anaconda3\envs\env_from_file\Lib\site-packages\urllib3\connection.py", line 174, in _new_conn
        conn = connection.create_connection(
               ^^^^^^^^^^^^^^^^^^^^^^^^^^^^^
      File "C:\Users\mahan\anaconda3\envs\env_from_file\Lib\site-packages\urllib3\util\connection.py", line 72, in create_connection
        for res in socket.getaddrinfo(host, port, family, socket.SOCK_STREAM):
                   ^^^^^^^^^^^^^^^^^^^^^^^^^^^^^^^^^^^^^^^^^^^^^^^^^^^^^^^^^^
      File "C:\Users\mahan\anaconda3\envs\env_from_file\Lib\socket.py", line 962, in getaddrinfo
        for res in _socket.getaddrinfo(host, port, family, type, proto, flags):
                   ^^^^^^^^^^^^^^^^^^^^^^^^^^^^^^^^^^^^^^^^^^^^^^^^^^^^^^^^^^^
    socket.gaierror: [Errno 11001] getaddrinfo failed
    
    During handling of the above exception, another exception occurred:
    
    Traceback (most recent call last):
      File "C:\Users\mahan\anaconda3\envs\env_from_file\Lib\site-packages\urllib3\connectionpool.py", line 715, in urlopen
        httplib_response = self._make_request(
                           ^^^^^^^^^^^^^^^^^^^
      File "C:\Users\mahan\anaconda3\envs\env_from_file\Lib\site-packages\urllib3\connectionpool.py", line 404, in _make_request
        self._validate_conn(conn)
      File "C:\Users\mahan\anaconda3\envs\env_from_file\Lib\site-packages\urllib3\connectionpool.py", line 1058, in _validate_conn
        conn.connect()
      File "C:\Users\mahan\anaconda3\envs\env_from_file\Lib\site-packages\urllib3\connection.py", line 363, in connect
        self.sock = conn = self._new_conn()
                           ^^^^^^^^^^^^^^^^
      File "C:\Users\mahan\anaconda3\envs\env_from_file\Lib\site-packages\urllib3\connection.py", line 186, in _new_conn
        raise NewConnectionError(
    urllib3.exceptions.NewConnectionError: <urllib3.connection.HTTPSConnection object at 0x000001C8EED71290>: Failed to establish a new connection: [Errno 11001] getaddrinfo failed
    
    During handling of the above exception, another exception occurred:
    
    Traceback (most recent call last):
      File "C:\Users\mahan\anaconda3\envs\env_from_file\Lib\site-packages\requests\adapters.py", line 486, in send
        resp = conn.urlopen(
               ^^^^^^^^^^^^^
      File "C:\Users\mahan\anaconda3\envs\env_from_file\Lib\site-packages\urllib3\connectionpool.py", line 799, in urlopen
        retries = retries.increment(
                  ^^^^^^^^^^^^^^^^^^
      File "C:\Users\mahan\anaconda3\envs\env_from_file\Lib\site-packages\urllib3\util\retry.py", line 592, in increment
        raise MaxRetryError(_pool, url, error or ResponseError(cause))
    urllib3.exceptions.MaxRetryError: HTTPSConnectionPool(host='apiconnect.angelbroking.com', port=443): Max retries exceeded with url: /rest/secure/angelbroking/historical/v1/getCandleData (Caused by NewConnectionError('<urllib3.connection.HTTPSConnection object at 0x000001C8EED71290>: Failed to establish a new connection: [Errno 11001] getaddrinfo failed'))
    
    During handling of the above exception, another exception occurred:
    
    Traceback (most recent call last):
      File "C:\Users\mahan\AppData\Local\Temp\ipykernel_9460\3159352199.py", line 18, in <module>
        candel_data = smartApi.getCandleData(historicParam)
                      ^^^^^^^^^^^^^^^^^^^^^^^^^^^^^^^^^^^^^
      File "C:\Users\mahan\anaconda3\envs\env_from_file\Lib\site-packages\SmartApi\smartConnect.py", line 430, in getCandleData
        getCandleDataResponse=self._postRequest("api.candle.data",historicDataParams)
                              ^^^^^^^^^^^^^^^^^^^^^^^^^^^^^^^^^^^^^^^^^^^^^^^^^^^^^^^
      File "C:\Users\mahan\anaconda3\envs\env_from_file\Lib\site-packages\SmartApi\smartConnect.py", line 228, in _postRequest
        return self._request(route, "POST", params)
               ^^^^^^^^^^^^^^^^^^^^^^^^^^^^^^^^^^^^
      File "C:\Users\mahan\anaconda3\envs\env_from_file\Lib\site-packages\SmartApi\smartConnect.py", line 188, in _request
        raise e
      File "C:\Users\mahan\anaconda3\envs\env_from_file\Lib\site-packages\SmartApi\smartConnect.py", line 177, in _request
        r = requests.request(method,
            ^^^^^^^^^^^^^^^^^^^^^^^^
      File "C:\Users\mahan\anaconda3\envs\env_from_file\Lib\site-packages\requests\api.py", line 59, in request
        return session.request(method=method, url=url, **kwargs)
               ^^^^^^^^^^^^^^^^^^^^^^^^^^^^^^^^^^^^^^^^^^^^^^^^^
      File "C:\Users\mahan\anaconda3\envs\env_from_file\Lib\site-packages\requests\sessions.py", line 589, in request
        resp = self.send(prep, **send_kwargs)
               ^^^^^^^^^^^^^^^^^^^^^^^^^^^^^^
      File "C:\Users\mahan\anaconda3\envs\env_from_file\Lib\site-packages\requests\sessions.py", line 703, in send
        r = adapter.send(request, **kwargs)
            ^^^^^^^^^^^^^^^^^^^^^^^^^^^^^^^
      File "C:\Users\mahan\anaconda3\envs\env_from_file\Lib\site-packages\requests\adapters.py", line 519, in send
        raise ConnectionError(e, request=request)
    requests.exceptions.ConnectionError: HTTPSConnectionPool(host='apiconnect.angelbroking.com', port=443): Max retries exceeded with url: /rest/secure/angelbroking/historical/v1/getCandleData (Caused by NewConnectionError('<urllib3.connection.HTTPSConnection object at 0x000001C8EED71290>: Failed to establish a new connection: [Errno 11001] getaddrinfo failed'))
[E 240131 12:47:05 3159352199:20] Historic Api failed: HTTPSConnectionPool(host='apiconnect.angelbroking.com', port=443): Max retries exceeded with url: /rest/secure/angelbroking/historical/v1/getCandleData (Caused by NewConnectionError('<urllib3.connection.HTTPSConnection object at 0x000001C8EFE49E50>: Failed to establish a new connection: [Errno 11001] getaddrinfo failed'))
    Traceback (most recent call last):
      File "C:\Users\mahan\anaconda3\envs\env_from_file\Lib\site-packages\urllib3\connection.py", line 174, in _new_conn
        conn = connection.create_connection(
               ^^^^^^^^^^^^^^^^^^^^^^^^^^^^^
      File "C:\Users\mahan\anaconda3\envs\env_from_file\Lib\site-packages\urllib3\util\connection.py", line 72, in create_connection
        for res in socket.getaddrinfo(host, port, family, socket.SOCK_STREAM):
                   ^^^^^^^^^^^^^^^^^^^^^^^^^^^^^^^^^^^^^^^^^^^^^^^^^^^^^^^^^^
      File "C:\Users\mahan\anaconda3\envs\env_from_file\Lib\socket.py", line 962, in getaddrinfo
        for res in _socket.getaddrinfo(host, port, family, type, proto, flags):
                   ^^^^^^^^^^^^^^^^^^^^^^^^^^^^^^^^^^^^^^^^^^^^^^^^^^^^^^^^^^^
    socket.gaierror: [Errno 11001] getaddrinfo failed
    
    During handling of the above exception, another exception occurred:
    
    Traceback (most recent call last):
      File "C:\Users\mahan\anaconda3\envs\env_from_file\Lib\site-packages\urllib3\connectionpool.py", line 715, in urlopen
        httplib_response = self._make_request(
                           ^^^^^^^^^^^^^^^^^^^
      File "C:\Users\mahan\anaconda3\envs\env_from_file\Lib\site-packages\urllib3\connectionpool.py", line 404, in _make_request
        self._validate_conn(conn)
      File "C:\Users\mahan\anaconda3\envs\env_from_file\Lib\site-packages\urllib3\connectionpool.py", line 1058, in _validate_conn
        conn.connect()
      File "C:\Users\mahan\anaconda3\envs\env_from_file\Lib\site-packages\urllib3\connection.py", line 363, in connect
        self.sock = conn = self._new_conn()
                           ^^^^^^^^^^^^^^^^
      File "C:\Users\mahan\anaconda3\envs\env_from_file\Lib\site-packages\urllib3\connection.py", line 186, in _new_conn
        raise NewConnectionError(
    urllib3.exceptions.NewConnectionError: <urllib3.connection.HTTPSConnection object at 0x000001C8EFE49E50>: Failed to establish a new connection: [Errno 11001] getaddrinfo failed
    
    During handling of the above exception, another exception occurred:
    
    Traceback (most recent call last):
      File "C:\Users\mahan\anaconda3\envs\env_from_file\Lib\site-packages\requests\adapters.py", line 486, in send
        resp = conn.urlopen(
               ^^^^^^^^^^^^^
      File "C:\Users\mahan\anaconda3\envs\env_from_file\Lib\site-packages\urllib3\connectionpool.py", line 799, in urlopen
        retries = retries.increment(
                  ^^^^^^^^^^^^^^^^^^
      File "C:\Users\mahan\anaconda3\envs\env_from_file\Lib\site-packages\urllib3\util\retry.py", line 592, in increment
        raise MaxRetryError(_pool, url, error or ResponseError(cause))
    urllib3.exceptions.MaxRetryError: HTTPSConnectionPool(host='apiconnect.angelbroking.com', port=443): Max retries exceeded with url: /rest/secure/angelbroking/historical/v1/getCandleData (Caused by NewConnectionError('<urllib3.connection.HTTPSConnection object at 0x000001C8EFE49E50>: Failed to establish a new connection: [Errno 11001] getaddrinfo failed'))
    
    During handling of the above exception, another exception occurred:
    
    Traceback (most recent call last):
      File "C:\Users\mahan\AppData\Local\Temp\ipykernel_9460\3159352199.py", line 18, in <module>
        candel_data = smartApi.getCandleData(historicParam)
                      ^^^^^^^^^^^^^^^^^^^^^^^^^^^^^^^^^^^^^
      File "C:\Users\mahan\anaconda3\envs\env_from_file\Lib\site-packages\SmartApi\smartConnect.py", line 430, in getCandleData
        getCandleDataResponse=self._postRequest("api.candle.data",historicDataParams)
                              ^^^^^^^^^^^^^^^^^^^^^^^^^^^^^^^^^^^^^^^^^^^^^^^^^^^^^^^
      File "C:\Users\mahan\anaconda3\envs\env_from_file\Lib\site-packages\SmartApi\smartConnect.py", line 228, in _postRequest
        return self._request(route, "POST", params)
               ^^^^^^^^^^^^^^^^^^^^^^^^^^^^^^^^^^^^
      File "C:\Users\mahan\anaconda3\envs\env_from_file\Lib\site-packages\SmartApi\smartConnect.py", line 188, in _request
        raise e
      File "C:\Users\mahan\anaconda3\envs\env_from_file\Lib\site-packages\SmartApi\smartConnect.py", line 177, in _request
        r = requests.request(method,
            ^^^^^^^^^^^^^^^^^^^^^^^^
      File "C:\Users\mahan\anaconda3\envs\env_from_file\Lib\site-packages\requests\api.py", line 59, in request
        return session.request(method=method, url=url, **kwargs)
               ^^^^^^^^^^^^^^^^^^^^^^^^^^^^^^^^^^^^^^^^^^^^^^^^^
      File "C:\Users\mahan\anaconda3\envs\env_from_file\Lib\site-packages\requests\sessions.py", line 589, in request
        resp = self.send(prep, **send_kwargs)
               ^^^^^^^^^^^^^^^^^^^^^^^^^^^^^^
      File "C:\Users\mahan\anaconda3\envs\env_from_file\Lib\site-packages\requests\sessions.py", line 703, in send
        r = adapter.send(request, **kwargs)
            ^^^^^^^^^^^^^^^^^^^^^^^^^^^^^^^
      File "C:\Users\mahan\anaconda3\envs\env_from_file\Lib\site-packages\requests\adapters.py", line 519, in send
        raise ConnectionError(e, request=request)
    requests.exceptions.ConnectionError: HTTPSConnectionPool(host='apiconnect.angelbroking.com', port=443): Max retries exceeded with url: /rest/secure/angelbroking/historical/v1/getCandleData (Caused by NewConnectionError('<urllib3.connection.HTTPSConnection object at 0x000001C8EFE49E50>: Failed to establish a new connection: [Errno 11001] getaddrinfo failed'))
[E 240131 13:28:35 2501600536:20] Historic Api failed: HTTPSConnectionPool(host='apiconnect.angelbroking.com', port=443): Max retries exceeded with url: /rest/secure/angelbroking/historical/v1/getCandleData (Caused by NewConnectionError('<urllib3.connection.HTTPSConnection object at 0x000001C8EFE595D0>: Failed to establish a new connection: [Errno 11001] getaddrinfo failed'))
    Traceback (most recent call last):
      File "C:\Users\mahan\anaconda3\envs\env_from_file\Lib\site-packages\urllib3\connection.py", line 174, in _new_conn
        conn = connection.create_connection(
               ^^^^^^^^^^^^^^^^^^^^^^^^^^^^^
      File "C:\Users\mahan\anaconda3\envs\env_from_file\Lib\site-packages\urllib3\util\connection.py", line 72, in create_connection
        for res in socket.getaddrinfo(host, port, family, socket.SOCK_STREAM):
                   ^^^^^^^^^^^^^^^^^^^^^^^^^^^^^^^^^^^^^^^^^^^^^^^^^^^^^^^^^^
      File "C:\Users\mahan\anaconda3\envs\env_from_file\Lib\socket.py", line 962, in getaddrinfo
        for res in _socket.getaddrinfo(host, port, family, type, proto, flags):
                   ^^^^^^^^^^^^^^^^^^^^^^^^^^^^^^^^^^^^^^^^^^^^^^^^^^^^^^^^^^^
    socket.gaierror: [Errno 11001] getaddrinfo failed
    
    During handling of the above exception, another exception occurred:
    
    Traceback (most recent call last):
      File "C:\Users\mahan\anaconda3\envs\env_from_file\Lib\site-packages\urllib3\connectionpool.py", line 715, in urlopen
        httplib_response = self._make_request(
                           ^^^^^^^^^^^^^^^^^^^
      File "C:\Users\mahan\anaconda3\envs\env_from_file\Lib\site-packages\urllib3\connectionpool.py", line 404, in _make_request
        self._validate_conn(conn)
      File "C:\Users\mahan\anaconda3\envs\env_from_file\Lib\site-packages\urllib3\connectionpool.py", line 1058, in _validate_conn
        conn.connect()
      File "C:\Users\mahan\anaconda3\envs\env_from_file\Lib\site-packages\urllib3\connection.py", line 363, in connect
        self.sock = conn = self._new_conn()
                           ^^^^^^^^^^^^^^^^
      File "C:\Users\mahan\anaconda3\envs\env_from_file\Lib\site-packages\urllib3\connection.py", line 186, in _new_conn
        raise NewConnectionError(
    urllib3.exceptions.NewConnectionError: <urllib3.connection.HTTPSConnection object at 0x000001C8EFE595D0>: Failed to establish a new connection: [Errno 11001] getaddrinfo failed
    
    During handling of the above exception, another exception occurred:
    
    Traceback (most recent call last):
      File "C:\Users\mahan\anaconda3\envs\env_from_file\Lib\site-packages\requests\adapters.py", line 486, in send
        resp = conn.urlopen(
               ^^^^^^^^^^^^^
      File "C:\Users\mahan\anaconda3\envs\env_from_file\Lib\site-packages\urllib3\connectionpool.py", line 799, in urlopen
        retries = retries.increment(
                  ^^^^^^^^^^^^^^^^^^
      File "C:\Users\mahan\anaconda3\envs\env_from_file\Lib\site-packages\urllib3\util\retry.py", line 592, in increment
        raise MaxRetryError(_pool, url, error or ResponseError(cause))
    urllib3.exceptions.MaxRetryError: HTTPSConnectionPool(host='apiconnect.angelbroking.com', port=443): Max retries exceeded with url: /rest/secure/angelbroking/historical/v1/getCandleData (Caused by NewConnectionError('<urllib3.connection.HTTPSConnection object at 0x000001C8EFE595D0>: Failed to establish a new connection: [Errno 11001] getaddrinfo failed'))
    
    During handling of the above exception, another exception occurred:
    
    Traceback (most recent call last):
      File "C:\Users\mahan\AppData\Local\Temp\ipykernel_9460\2501600536.py", line 18, in <module>
        candel_data = smartApi.getCandleData(historicParam)
                      ^^^^^^^^^^^^^^^^^^^^^^^^^^^^^^^^^^^^^
      File "C:\Users\mahan\anaconda3\envs\env_from_file\Lib\site-packages\SmartApi\smartConnect.py", line 430, in getCandleData
        getCandleDataResponse=self._postRequest("api.candle.data",historicDataParams)
                              ^^^^^^^^^^^^^^^^^^^^^^^^^^^^^^^^^^^^^^^^^^^^^^^^^^^^^^^
      File "C:\Users\mahan\anaconda3\envs\env_from_file\Lib\site-packages\SmartApi\smartConnect.py", line 228, in _postRequest
        return self._request(route, "POST", params)
               ^^^^^^^^^^^^^^^^^^^^^^^^^^^^^^^^^^^^
      File "C:\Users\mahan\anaconda3\envs\env_from_file\Lib\site-packages\SmartApi\smartConnect.py", line 188, in _request
        raise e
      File "C:\Users\mahan\anaconda3\envs\env_from_file\Lib\site-packages\SmartApi\smartConnect.py", line 177, in _request
        r = requests.request(method,
            ^^^^^^^^^^^^^^^^^^^^^^^^
      File "C:\Users\mahan\anaconda3\envs\env_from_file\Lib\site-packages\requests\api.py", line 59, in request
        return session.request(method=method, url=url, **kwargs)
               ^^^^^^^^^^^^^^^^^^^^^^^^^^^^^^^^^^^^^^^^^^^^^^^^^
      File "C:\Users\mahan\anaconda3\envs\env_from_file\Lib\site-packages\requests\sessions.py", line 589, in request
        resp = self.send(prep, **send_kwargs)
               ^^^^^^^^^^^^^^^^^^^^^^^^^^^^^^
      File "C:\Users\mahan\anaconda3\envs\env_from_file\Lib\site-packages\requests\sessions.py", line 703, in send
        r = adapter.send(request, **kwargs)
            ^^^^^^^^^^^^^^^^^^^^^^^^^^^^^^^
      File "C:\Users\mahan\anaconda3\envs\env_from_file\Lib\site-packages\requests\adapters.py", line 519, in send
        raise ConnectionError(e, request=request)
    requests.exceptions.ConnectionError: HTTPSConnectionPool(host='apiconnect.angelbroking.com', port=443): Max retries exceeded with url: /rest/secure/angelbroking/historical/v1/getCandleData (Caused by NewConnectionError('<urllib3.connection.HTTPSConnection object at 0x000001C8EFE595D0>: Failed to establish a new connection: [Errno 11001] getaddrinfo failed'))
[W 240131 19:45:52 smartWebSocketV2:318] Attempting to resubscribe/reconnect (Attempt 1)...
[W 240131 19:46:02 smartWebSocketV2:318] Attempting to resubscribe/reconnect (Attempt 2)...
[E 240131 19:46:12 1445902553:39] Connection closed
[W 240131 19:46:12 smartWebSocketV2:342] Connection closed due to max retry attempts reached.
[I 240131 19:46:12 1445902553:42] Close
[I 240131 19:46:12 1445902553:42] Close
[I 240131 19:46:12 1445902553:42] Close
[E 240131 20:13:57 1167164800:21] Historic Api failed: type object 'datetime.datetime' has no attribute 'timedelta'
    Traceback (most recent call last):
      File "C:\Users\mahan\AppData\Local\Temp\ipykernel_7500\1167164800.py", line 7, in <module>
        "fromdate": f'{date.today()-datetime.timedelta(90)} 09:15',
                                    ^^^^^^^^^^^^^^^^^^
    AttributeError: type object 'datetime.datetime' has no attribute 'timedelta'
[E 240131 20:23:19 3544240695:21] Historic Api failed: Couldn't parse the JSON response received from the server: b''
    Traceback (most recent call last):
      File "C:\Users\mahan\anaconda3\envs\env_from_file\Lib\site-packages\SmartApi\smartConnect.py", line 196, in _request
        data = json.loads(r.content.decode("utf8"))
               ^^^^^^^^^^^^^^^^^^^^^^^^^^^^^^^^^^^^
      File "C:\Users\mahan\anaconda3\envs\env_from_file\Lib\json\__init__.py", line 346, in loads
        return _default_decoder.decode(s)
               ^^^^^^^^^^^^^^^^^^^^^^^^^^
      File "C:\Users\mahan\anaconda3\envs\env_from_file\Lib\json\decoder.py", line 337, in decode
        obj, end = self.raw_decode(s, idx=_w(s, 0).end())
                   ^^^^^^^^^^^^^^^^^^^^^^^^^^^^^^^^^^^^^^
      File "C:\Users\mahan\anaconda3\envs\env_from_file\Lib\json\decoder.py", line 355, in raw_decode
        raise JSONDecodeError("Expecting value", s, err.value) from None
    json.decoder.JSONDecodeError: Expecting value: line 1 column 1 (char 0)
    
    During handling of the above exception, another exception occurred:
    
    Traceback (most recent call last):
      File "C:\Users\mahan\AppData\Local\Temp\ipykernel_7500\3544240695.py", line 19, in <module>
        candel_data = smartApi.getCandleData(historicParam)
                      ^^^^^^^^^^^^^^^^^^^^^^^^^^^^^^^^^^^^^
      File "C:\Users\mahan\anaconda3\envs\env_from_file\Lib\site-packages\SmartApi\smartConnect.py", line 430, in getCandleData
        getCandleDataResponse=self._postRequest("api.candle.data",historicDataParams)
                              ^^^^^^^^^^^^^^^^^^^^^^^^^^^^^^^^^^^^^^^^^^^^^^^^^^^^^^^
      File "C:\Users\mahan\anaconda3\envs\env_from_file\Lib\site-packages\SmartApi\smartConnect.py", line 228, in _postRequest
        return self._request(route, "POST", params)
               ^^^^^^^^^^^^^^^^^^^^^^^^^^^^^^^^^^^^
      File "C:\Users\mahan\anaconda3\envs\env_from_file\Lib\site-packages\SmartApi\smartConnect.py", line 199, in _request
        raise ex.DataException("Couldn't parse the JSON response received from the server: {content}".format(
    SmartApi.smartExceptions.DataException: Couldn't parse the JSON response received from the server: b''
[E 240131 20:23:54 3544240695:21] Historic Api failed: Couldn't parse the JSON response received from the server: b''
    Traceback (most recent call last):
      File "C:\Users\mahan\anaconda3\envs\env_from_file\Lib\site-packages\SmartApi\smartConnect.py", line 196, in _request
        data = json.loads(r.content.decode("utf8"))
               ^^^^^^^^^^^^^^^^^^^^^^^^^^^^^^^^^^^^
      File "C:\Users\mahan\anaconda3\envs\env_from_file\Lib\json\__init__.py", line 346, in loads
        return _default_decoder.decode(s)
               ^^^^^^^^^^^^^^^^^^^^^^^^^^
      File "C:\Users\mahan\anaconda3\envs\env_from_file\Lib\json\decoder.py", line 337, in decode
        obj, end = self.raw_decode(s, idx=_w(s, 0).end())
                   ^^^^^^^^^^^^^^^^^^^^^^^^^^^^^^^^^^^^^^
      File "C:\Users\mahan\anaconda3\envs\env_from_file\Lib\json\decoder.py", line 355, in raw_decode
        raise JSONDecodeError("Expecting value", s, err.value) from None
    json.decoder.JSONDecodeError: Expecting value: line 1 column 1 (char 0)
    
    During handling of the above exception, another exception occurred:
    
    Traceback (most recent call last):
      File "C:\Users\mahan\AppData\Local\Temp\ipykernel_7500\3544240695.py", line 19, in <module>
        candel_data = smartApi.getCandleData(historicParam)
                      ^^^^^^^^^^^^^^^^^^^^^^^^^^^^^^^^^^^^^
      File "C:\Users\mahan\anaconda3\envs\env_from_file\Lib\site-packages\SmartApi\smartConnect.py", line 430, in getCandleData
        getCandleDataResponse=self._postRequest("api.candle.data",historicDataParams)
                              ^^^^^^^^^^^^^^^^^^^^^^^^^^^^^^^^^^^^^^^^^^^^^^^^^^^^^^^
      File "C:\Users\mahan\anaconda3\envs\env_from_file\Lib\site-packages\SmartApi\smartConnect.py", line 228, in _postRequest
        return self._request(route, "POST", params)
               ^^^^^^^^^^^^^^^^^^^^^^^^^^^^^^^^^^^^
      File "C:\Users\mahan\anaconda3\envs\env_from_file\Lib\site-packages\SmartApi\smartConnect.py", line 199, in _request
        raise ex.DataException("Couldn't parse the JSON response received from the server: {content}".format(
    SmartApi.smartExceptions.DataException: Couldn't parse the JSON response received from the server: b''
[E 240131 20:26:27 1635159846:21] Historic Api failed: Couldn't parse the JSON response received from the server: b''
    Traceback (most recent call last):
      File "C:\Users\mahan\anaconda3\envs\env_from_file\Lib\site-packages\SmartApi\smartConnect.py", line 196, in _request
        data = json.loads(r.content.decode("utf8"))
               ^^^^^^^^^^^^^^^^^^^^^^^^^^^^^^^^^^^^
      File "C:\Users\mahan\anaconda3\envs\env_from_file\Lib\json\__init__.py", line 346, in loads
        return _default_decoder.decode(s)
               ^^^^^^^^^^^^^^^^^^^^^^^^^^
      File "C:\Users\mahan\anaconda3\envs\env_from_file\Lib\json\decoder.py", line 337, in decode
        obj, end = self.raw_decode(s, idx=_w(s, 0).end())
                   ^^^^^^^^^^^^^^^^^^^^^^^^^^^^^^^^^^^^^^
      File "C:\Users\mahan\anaconda3\envs\env_from_file\Lib\json\decoder.py", line 355, in raw_decode
        raise JSONDecodeError("Expecting value", s, err.value) from None
    json.decoder.JSONDecodeError: Expecting value: line 1 column 1 (char 0)
    
    During handling of the above exception, another exception occurred:
    
    Traceback (most recent call last):
      File "C:\Users\mahan\AppData\Local\Temp\ipykernel_7500\1635159846.py", line 19, in <module>
        candel_data = smartApi.getCandleData(historicParam)
                      ^^^^^^^^^^^^^^^^^^^^^^^^^^^^^^^^^^^^^
      File "C:\Users\mahan\anaconda3\envs\env_from_file\Lib\site-packages\SmartApi\smartConnect.py", line 430, in getCandleData
        getCandleDataResponse=self._postRequest("api.candle.data",historicDataParams)
                              ^^^^^^^^^^^^^^^^^^^^^^^^^^^^^^^^^^^^^^^^^^^^^^^^^^^^^^^
      File "C:\Users\mahan\anaconda3\envs\env_from_file\Lib\site-packages\SmartApi\smartConnect.py", line 228, in _postRequest
        return self._request(route, "POST", params)
               ^^^^^^^^^^^^^^^^^^^^^^^^^^^^^^^^^^^^
      File "C:\Users\mahan\anaconda3\envs\env_from_file\Lib\site-packages\SmartApi\smartConnect.py", line 199, in _request
        raise ex.DataException("Couldn't parse the JSON response received from the server: {content}".format(
    SmartApi.smartExceptions.DataException: Couldn't parse the JSON response received from the server: b''
[E 240131 20:27:59 3527593154:21] Historic Api failed: Couldn't parse the JSON response received from the server: b''
    Traceback (most recent call last):
      File "C:\Users\mahan\anaconda3\envs\env_from_file\Lib\site-packages\SmartApi\smartConnect.py", line 196, in _request
        data = json.loads(r.content.decode("utf8"))
               ^^^^^^^^^^^^^^^^^^^^^^^^^^^^^^^^^^^^
      File "C:\Users\mahan\anaconda3\envs\env_from_file\Lib\json\__init__.py", line 346, in loads
        return _default_decoder.decode(s)
               ^^^^^^^^^^^^^^^^^^^^^^^^^^
      File "C:\Users\mahan\anaconda3\envs\env_from_file\Lib\json\decoder.py", line 337, in decode
        obj, end = self.raw_decode(s, idx=_w(s, 0).end())
                   ^^^^^^^^^^^^^^^^^^^^^^^^^^^^^^^^^^^^^^
      File "C:\Users\mahan\anaconda3\envs\env_from_file\Lib\json\decoder.py", line 355, in raw_decode
        raise JSONDecodeError("Expecting value", s, err.value) from None
    json.decoder.JSONDecodeError: Expecting value: line 1 column 1 (char 0)
    
    During handling of the above exception, another exception occurred:
    
    Traceback (most recent call last):
      File "C:\Users\mahan\AppData\Local\Temp\ipykernel_7500\3527593154.py", line 19, in <module>
        candel_data = smartApi.getCandleData(historicParam)
                      ^^^^^^^^^^^^^^^^^^^^^^^^^^^^^^^^^^^^^
      File "C:\Users\mahan\anaconda3\envs\env_from_file\Lib\site-packages\SmartApi\smartConnect.py", line 430, in getCandleData
        getCandleDataResponse=self._postRequest("api.candle.data",historicDataParams)
                              ^^^^^^^^^^^^^^^^^^^^^^^^^^^^^^^^^^^^^^^^^^^^^^^^^^^^^^^
      File "C:\Users\mahan\anaconda3\envs\env_from_file\Lib\site-packages\SmartApi\smartConnect.py", line 228, in _postRequest
        return self._request(route, "POST", params)
               ^^^^^^^^^^^^^^^^^^^^^^^^^^^^^^^^^^^^
      File "C:\Users\mahan\anaconda3\envs\env_from_file\Lib\site-packages\SmartApi\smartConnect.py", line 199, in _request
        raise ex.DataException("Couldn't parse the JSON response received from the server: {content}".format(
    SmartApi.smartExceptions.DataException: Couldn't parse the JSON response received from the server: b''
[E 240131 21:39:45 3981906559:20] Historic Api failed: Couldn't parse the JSON response received from the server: b''
    Traceback (most recent call last):
      File "C:\Users\mahan\anaconda3\envs\env_from_file\Lib\site-packages\SmartApi\smartConnect.py", line 196, in _request
        data = json.loads(r.content.decode("utf8"))
               ^^^^^^^^^^^^^^^^^^^^^^^^^^^^^^^^^^^^
      File "C:\Users\mahan\anaconda3\envs\env_from_file\Lib\json\__init__.py", line 346, in loads
        return _default_decoder.decode(s)
               ^^^^^^^^^^^^^^^^^^^^^^^^^^
      File "C:\Users\mahan\anaconda3\envs\env_from_file\Lib\json\decoder.py", line 337, in decode
        obj, end = self.raw_decode(s, idx=_w(s, 0).end())
                   ^^^^^^^^^^^^^^^^^^^^^^^^^^^^^^^^^^^^^^
      File "C:\Users\mahan\anaconda3\envs\env_from_file\Lib\json\decoder.py", line 355, in raw_decode
        raise JSONDecodeError("Expecting value", s, err.value) from None
    json.decoder.JSONDecodeError: Expecting value: line 1 column 1 (char 0)
    
    During handling of the above exception, another exception occurred:
    
    Traceback (most recent call last):
      File "C:\Users\mahan\AppData\Local\Temp\ipykernel_7500\3981906559.py", line 18, in <module>
        candel_data = smartApi.getCandleData(historicParam)
                      ^^^^^^^^^^^^^^^^^^^^^^^^^^^^^^^^^^^^^
      File "C:\Users\mahan\anaconda3\envs\env_from_file\Lib\site-packages\SmartApi\smartConnect.py", line 430, in getCandleData
        getCandleDataResponse=self._postRequest("api.candle.data",historicDataParams)
                              ^^^^^^^^^^^^^^^^^^^^^^^^^^^^^^^^^^^^^^^^^^^^^^^^^^^^^^^
      File "C:\Users\mahan\anaconda3\envs\env_from_file\Lib\site-packages\SmartApi\smartConnect.py", line 228, in _postRequest
        return self._request(route, "POST", params)
               ^^^^^^^^^^^^^^^^^^^^^^^^^^^^^^^^^^^^
      File "C:\Users\mahan\anaconda3\envs\env_from_file\Lib\site-packages\SmartApi\smartConnect.py", line 199, in _request
        raise ex.DataException("Couldn't parse the JSON response received from the server: {content}".format(
    SmartApi.smartExceptions.DataException: Couldn't parse the JSON response received from the server: b''
[W 240131 22:14:25 smartWebSocketV2:318] Attempting to resubscribe/reconnect (Attempt 1)...
[W 240131 22:14:35 smartWebSocketV2:318] Attempting to resubscribe/reconnect (Attempt 2)...
[E 240131 22:14:46 1445902553:39] Connection closed
[W 240131 22:14:46 smartWebSocketV2:342] Connection closed due to max retry attempts reached.
[I 240131 22:14:46 1445902553:42] Close
[I 240131 22:14:46 1445902553:42] Close
[I 240131 22:14:46 1445902553:42] Close
[W 240131 22:16:42 smartWebSocketV2:318] Attempting to resubscribe/reconnect (Attempt 1)...
[W 240131 22:16:52 smartWebSocketV2:318] Attempting to resubscribe/reconnect (Attempt 2)...
[E 240131 22:17:02 1445902553:39] Connection closed
[W 240131 22:17:02 smartWebSocketV2:342] Connection closed due to max retry attempts reached.
[I 240131 22:17:02 1445902553:42] Close
[I 240131 22:17:02 1445902553:42] Close
[I 240131 22:17:02 1445902553:42] Close
[W 240131 22:48:36 smartWebSocketV2:318] Attempting to resubscribe/reconnect (Attempt 1)...
[W 240131 22:48:46 smartWebSocketV2:318] Attempting to resubscribe/reconnect (Attempt 2)...
[E 240131 22:48:56 1464731737:39] Connection closed
[W 240131 22:48:56 smartWebSocketV2:342] Connection closed due to max retry attempts reached.
[I 240131 22:48:56 1464731737:42] Close
[I 240131 22:48:56 1464731737:42] Close
[I 240131 22:48:56 1464731737:42] Close
