[E 240130 19:31:02 smartWebSocketV2:304] Error occurred during WebSocket connection: WebSocketApp.run_forever() got an unexpected keyword argument 'ping_payload'
[E 240130 19:54:55 smartWebSocketV2:304] Error occurred during WebSocket connection: WebSocketApp.run_forever() got an unexpected keyword argument 'ping_payload'
[W 240130 20:48:03 smartWebSocketV2:318] Attempting to resubscribe/reconnect (Attempt 1)...
[W 240130 20:48:13 smartWebSocketV2:318] Attempting to resubscribe/reconnect (Attempt 2)...
[E 240130 20:48:23 1445902553:39] Connection closed
[W 240130 20:48:23 smartWebSocketV2:342] Connection closed due to max retry attempts reached.
[I 240130 20:48:23 1445902553:42] Close
[I 240130 20:48:23 1445902553:42] Close
[I 240130 20:48:23 1445902553:42] Close
[W 240130 20:49:44 smartWebSocketV2:318] Attempting to resubscribe/reconnect (Attempt 1)...
[W 240130 20:49:54 smartWebSocketV2:318] Attempting to resubscribe/reconnect (Attempt 2)...
[E 240130 20:50:04 1445902553:39] Connection closed
[W 240130 20:50:04 smartWebSocketV2:342] Connection closed due to max retry attempts reached.
[I 240130 20:50:04 1445902553:42] Close
[I 240130 20:50:04 1445902553:42] Close
[I 240130 20:50:04 1445902553:42] Close
[E 240130 23:48:50 2340537534:19] Historic Api failed: HTTPSConnectionPool(host='apiconnect.angelbroking.com', port=443): Max retries exceeded with url: /rest/secure/angelbroking/historical/v1/getCandleData (Caused by NewConnectionError('<urllib3.connection.HTTPSConnection object at 0x000001734F41A3D0>: Failed to establish a new connection: [Errno 11002] getaddrinfo failed'))
    Traceback (most recent call last):
      File "C:\Users\mahan\anaconda3\envs\env_from_file\Lib\site-packages\urllib3\connection.py", line 174, in _new_conn
        conn = connection.create_connection(
               ^^^^^^^^^^^^^^^^^^^^^^^^^^^^^
      File "C:\Users\mahan\anaconda3\envs\env_from_file\Lib\site-packages\urllib3\util\connection.py", line 72, in create_connection
        for res in socket.getaddrinfo(host, port, family, socket.SOCK_STREAM):
                   ^^^^^^^^^^^^^^^^^^^^^^^^^^^^^^^^^^^^^^^^^^^^^^^^^^^^^^^^^^
      File "C:\Users\mahan\anaconda3\envs\env_from_file\Lib\socket.py", line 962, in getaddrinfo
        for res in _socket.getaddrinfo(host, port, family, type, proto, flags):
                   ^^^^^^^^^^^^^^^^^^^^^^^^^^^^^^^^^^^^^^^^^^^^^^^^^^^^^^^^^^^
    socket.gaierror: [Errno 11002] getaddrinfo failed
    
    During handling of the above exception, another exception occurred:
    
    Traceback (most recent call last):
      File "C:\Users\mahan\anaconda3\envs\env_from_file\Lib\site-packages\urllib3\connectionpool.py", line 715, in urlopen
        httplib_response = self._make_request(
                           ^^^^^^^^^^^^^^^^^^^
      File "C:\Users\mahan\anaconda3\envs\env_from_file\Lib\site-packages\urllib3\connectionpool.py", line 404, in _make_request
        self._validate_conn(conn)
      File "C:\Users\mahan\anaconda3\envs\env_from_file\Lib\site-packages\urllib3\connectionpool.py", line 1058, in _validate_conn
        conn.connect()
      File "C:\Users\mahan\anaconda3\envs\env_from_file\Lib\site-packages\urllib3\connection.py", line 363, in connect
        self.sock = conn = self._new_conn()
                           ^^^^^^^^^^^^^^^^
      File "C:\Users\mahan\anaconda3\envs\env_from_file\Lib\site-packages\urllib3\connection.py", line 186, in _new_conn
        raise NewConnectionError(
    urllib3.exceptions.NewConnectionError: <urllib3.connection.HTTPSConnection object at 0x000001734F41A3D0>: Failed to establish a new connection: [Errno 11002] getaddrinfo failed
    
    During handling of the above exception, another exception occurred:
    
    Traceback (most recent call last):
      File "C:\Users\mahan\anaconda3\envs\env_from_file\Lib\site-packages\requests\adapters.py", line 486, in send
        resp = conn.urlopen(
               ^^^^^^^^^^^^^
      File "C:\Users\mahan\anaconda3\envs\env_from_file\Lib\site-packages\urllib3\connectionpool.py", line 799, in urlopen
        retries = retries.increment(
                  ^^^^^^^^^^^^^^^^^^
      File "C:\Users\mahan\anaconda3\envs\env_from_file\Lib\site-packages\urllib3\util\retry.py", line 592, in increment
        raise MaxRetryError(_pool, url, error or ResponseError(cause))
    urllib3.exceptions.MaxRetryError: HTTPSConnectionPool(host='apiconnect.angelbroking.com', port=443): Max retries exceeded with url: /rest/secure/angelbroking/historical/v1/getCandleData (Caused by NewConnectionError('<urllib3.connection.HTTPSConnection object at 0x000001734F41A3D0>: Failed to establish a new connection: [Errno 11002] getaddrinfo failed'))
    
    During handling of the above exception, another exception occurred:
    
    Traceback (most recent call last):
      File "C:\Users\mahan\AppData\Local\Temp\ipykernel_3176\2340537534.py", line 17, in <module>
        candel_data = smartApi.getCandleData(historicParam)
                      ^^^^^^^^^^^^^^^^^^^^^^^^^^^^^^^^^^^^^
      File "C:\Users\mahan\anaconda3\envs\env_from_file\Lib\site-packages\SmartApi\smartConnect.py", line 430, in getCandleData
        getCandleDataResponse=self._postRequest("api.candle.data",historicDataParams)
                              ^^^^^^^^^^^^^^^^^^^^^^^^^^^^^^^^^^^^^^^^^^^^^^^^^^^^^^^
      File "C:\Users\mahan\anaconda3\envs\env_from_file\Lib\site-packages\SmartApi\smartConnect.py", line 228, in _postRequest
        return self._request(route, "POST", params)
               ^^^^^^^^^^^^^^^^^^^^^^^^^^^^^^^^^^^^
      File "C:\Users\mahan\anaconda3\envs\env_from_file\Lib\site-packages\SmartApi\smartConnect.py", line 188, in _request
        raise e
      File "C:\Users\mahan\anaconda3\envs\env_from_file\Lib\site-packages\SmartApi\smartConnect.py", line 177, in _request
        r = requests.request(method,
            ^^^^^^^^^^^^^^^^^^^^^^^^
      File "C:\Users\mahan\anaconda3\envs\env_from_file\Lib\site-packages\requests\api.py", line 59, in request
        return session.request(method=method, url=url, **kwargs)
               ^^^^^^^^^^^^^^^^^^^^^^^^^^^^^^^^^^^^^^^^^^^^^^^^^
      File "C:\Users\mahan\anaconda3\envs\env_from_file\Lib\site-packages\requests\sessions.py", line 589, in request
        resp = self.send(prep, **send_kwargs)
               ^^^^^^^^^^^^^^^^^^^^^^^^^^^^^^
      File "C:\Users\mahan\anaconda3\envs\env_from_file\Lib\site-packages\requests\sessions.py", line 703, in send
        r = adapter.send(request, **kwargs)
            ^^^^^^^^^^^^^^^^^^^^^^^^^^^^^^^
      File "C:\Users\mahan\anaconda3\envs\env_from_file\Lib\site-packages\requests\adapters.py", line 519, in send
        raise ConnectionError(e, request=request)
    requests.exceptions.ConnectionError: HTTPSConnectionPool(host='apiconnect.angelbroking.com', port=443): Max retries exceeded with url: /rest/secure/angelbroking/historical/v1/getCandleData (Caused by NewConnectionError('<urllib3.connection.HTTPSConnection object at 0x000001734F41A3D0>: Failed to establish a new connection: [Errno 11002] getaddrinfo failed'))
